Workbook

Sheet COLA RAW DATA
A1: Data provided by SimFin | B1: Column2 | C1: Column3 | D1: Column4 | E1: Column5 | F1: Column6 | G1: Column7 | H1: Column8 | I1: Column9 | J1: Column10 | K1: Column11 | L1: Column12
A3: Profit & Loss statement
B4: in million USD | C4: FY '09 | D4: FY '10 | E4: FY '11 | F4: FY '12 | G4: FY '13 | H4: FY '14 | I4: FY '15 | J4: FY '16 | K4: FY '17 | L4: FY '18
B5: NET OPERATING REVENUES | C5: 30990 | D5: 35119 | E5: 46542 | F5: 48017 | G5: 46854 | H5: 45998 | I5: 44294 | J5: 41863 | K5: 35410 | L5: 31856
B6: Cost of goods sold | C6: 11088 | D6: 12693 | E6: 18215 | F6: 19053 | G6: 18421 | H6: 17889 | I6: 17482 | J6: 16465 | K6: 13255 | L6: 11770
B7: Gross Profit | C7: 19902 | D7: 22426 | E7: 28327 | F7: 28964 | G7: 28433 | H7: 28109 | I7: 26812 | J7: 25398 | K7: 22155 | L7: 20086
B8: Selling, general and administrative expenses | C8: 11358 | D8: 13194 | E8: 17422 | F8: 17738 | G8: 17310 | H8: 17218 | I8: 16427 | J8: 15262 | K8: 12654 | L8: 10307
B9: Other operating charges | C9: 313 | D9: 819 | E9: 732 | F9: 447 | G9: 895 | H9: 1183 | I9: 1657 | J9: 1510 | K9: 1902 | L9: 1079
B10: Operating Income | C10: 8231 | D10: 8413 | E10: 10173 | F10: 10779 | G10: 10228 | H10: 9708 | I10: 8728 | J10: 8626 | K10: 7599 | L10: 8700
B11: Interest income | C11: 249 | D11: 317 | E11: 483 | F11: 471 | G11: 534 | H11: 594 | I11: 613 | J11: 642 | K11: 677 | L11: 682
B12: Interest expense | C12: 355 | D12: 733 | E12: 417 | F12: 397 | G12: 463 | H12: 483 | I12: 856 | J12: 733 | K12: 841 | L12: 919
B13: Equity income (loss) - net | C13: 781 | D13: 1025 | E13: 690 | F13: 819 | G13: 602 | H13: 769 | I13: 489 | J13: 835 | K13: 1071 | L13: 1008
B14: Other income (loss) - net | C14: 40 | D14: 5185 | E14: 529 | F14: 137 | G14: 576 | H14: -1263 | I14: 631 | J14: -1234 | K14: -1764 | L14: -1121
B15: Income before income taxes | C15: 8946 | D15: 14207 | E15: 11458 | F15: 11809 | G15: 11477 | H15: 9325 | I15: 9605 | J15: 8136 | K15: 6742 | L15: 8350
B16: Income taxes | C16: 2040 | D16: 2370 | E16: 2812 | F16: 2723 | G16: 2851 | H16: 2201 | I16: 2239 | J16: 1586 | K16: 5560 | L16: 1623
... B18: Less: Net income attributable to noncontrolling interests | C18: 82 | D18: 50 | E18: 62 | F18: 67 | G18: 42 | H18: 26 | I18: 15 | J18: 23 | K18: 35 | L18: 42
B19: Net income from continuing operations | I19: 7366 | J19: 6550 | K19: 1182 | L19: 6727
B20: Income (Loss) from Discontinued Operations, Net of Tax, Including Portion Attributable to Noncontrolling Interest | I20: 0 | J20: 0 | K20: 101 | L20: -251
B21: NET INCOME ATTRIBUTABLE TO SHAREOWNERS OF THE COCA-COLA COMPANY | C21: 6824 | D21: 11787 | E21: 8584 | F21: 9019 | G21: 8584 | H21: 7098 | I21: 7351 | J21: 6527 | K21: 1248 | L21: 6434
A23: Balance Sheet
B24: in million USD | C24: FY '09 | D24: FY '10 | E24: FY '11 | F24: FY '12 | G24: FY '13 | H24: FY '14 | I24: FY '15 | J24: FY '16 | K24: FY '17 | L24: FY '18
B25: Assets
B26: Cash and cash equivalents | C26: 7021 | D26: 8517 | E26: 12803 | F26: 8442 | G26: 10414 | H26: 8958 | I26: 7309 | J26: 8555 | K26: 6006 | L26: 8926
B27: Short-term investments | C27: 2130 | D27: 2682 | E27: 1088 | F27: 5017 | G27: 6707 | H27: 9052 | I27: 8322 | J27: 9595 | K27: 9352 | L27: 2025
B28: Total cash, cash equivalents and short-term investments | C28: 9151 | D28: 11199 | E28: 13891 | F28: 13459 | G28: 17121 | H28: 18010 | I28: 15631 | J28: 18150 | K28: 15358 | L28: 10951
B29: Marketable securities | C29: 62 | D29: 138 | E29: 144 | F29: 3092 | G29: 3147 | H29: 3665 | I29: 4269 | J29: 4051 | K29: 5317 | L29: 5013
B30: Trade accounts receivable, less allowances | C30: 3758 | D30: 4430 | E30: 4920 | F30: 4759 | G30: 4873 | H30: 4466 | I30: 3941 | J30: 3856 | K30: 3667 | L30: 3396
B31: Inventories | C31: 2354 | D31: 2650 | E31: 3092 | F31: 3264 | G31: 3277 | H31: 3100 | I31: 2902 | J31: 2675 | K31: 2655 | L31: 2766
B32: Prepaid expenses and other assets | C32: 2226 | D32: 3162 | E32: 3450 | F32: 2781 | G32: 2886 | H32: 3066 | I32: 2752 | J32: 2481 | K32: 2000 | L32: 1962
B33: Assets held for sale | E33: 0 | F33: 2973 | G33: 0 | H33: 679 | I33: 3900 | J33: 0 | K33: 7329 | L33: 6546
B34: Assets held for sale | J34: 2797 | K34: 219 | L34: 0
B35: Total current assets | C35: 17551 | D35: 21579 | E35: 25497 | F35: 30328 | G35: 31304 | H35: 32986 | I35: 33395 | J35: 34010 | K35: 36545 | L35: 30634
B36: Equity method investments | C36: 6217 | D36: 6954 | E36: 7233 | F36: 9216 | G36: 10393 | H36: 9947 | I36: 12318 | J36: 16260 | K36: 20856 | L36: 19407
B37: Other investments | C37: 538 | D37: 631 | E37: 1141 | F37: 1232 | G37: 1119 | H37: 3678 | I37: 3470 | J37: 989 | K37: 1096 | L37: 867
B38: Other assets | C38: 1976 | D38: 2121 | E38: 3495 | F38: 3585 | G38: 4661 | H38: 4407 | I38: 4110 | J38: 4248 | K38: 4230 | L38: 4139
B39: Property, plant and equipment - net | C39: 9561 | D39: 14727 | E39: 14939 | F39: 14476 | G39: 14967 | H39: 14633 | I39: 12571 | J39: 10635 | K39: 8203 | L39: 8232
B40: Deferred income tax assets | K40: 330 | L40: 2667
B41: TRADEMARKS WITH INDEFINITE LIVES | C41: 6183 | D41: 6356 | E41: 6430 | F41: 6527 | G41: 6744 | H41: 6533 | I41: 5989 | J41: 6097 | K41: 6729 | L41: 6682
B42: BOTTLERS' FRANCHISE RIGHTS WITH INDEFINITE LIVES | C42: 1953 | D42: 7511 | E42: 7770 | F42: 7405 | G42: 7415 | H42: 6689 | I42: 6000 | J42: 3676 | K42: 138 | L42: 51
B43: Goodwill | C43: 4224 | D43: 11665 | E43: 12219 | F43: 12255 | G43: 12312 | H43: 12100 | I43: 11289 | J43: 10629 | K43: 9401 | L43: 10263
...

Sheet Profit & Loss Statement
A2: Profit & Loss Statement
A4: Fiscal Year | B4: FY '09 | C4: FY '10 | D4: FY '11 | E4: FY '12 | F4: FY '13 | G4: FY '14 | H4: FY '15 | I4: FY '16 | J4: FY '17 | K4: FY '18
A6: NET OPERATING REVENUES | B6: 30990 | C6: 35119 | D6: 46542 | E6: 48017 | F6: 46854 | G6: 45998 | H6: 44294 | I6: 41863 | J6: 35410 | K6: 31856
A7: Cost of goods sold | B7: 11088 | C7: 12693 | D7: 18215 | E7: 19053 | F7: 18421 | G7: 17889 | H7: 17482 | I7: 16465 | J7: 13255 | K7: 11770
A9: Gross Profit | B9: =B6-B7 -> 19902 | C9: =C6-C7 -> 22426 | D9: =D6-D7 -> 28327 | E9: =E6-E7 -> 28964 | F9: =F6-F7 -> 28433 | G9: =G6-G7 -> 28109 | H9: =H6-H7 -> 26812 | I9: =I6-I7 -> 25398 | ... K9: =K6-K7 -> 20086
A11: Selling, general and administrative expenses | B11: 11358 | C11: 13194 | D11: 17422 | E11: 17738 | F11: 17310 | G11: 17218 | H11: 16427 | I11: 15262 | J11: 12654 | K11: 10307
A12: Other operating charges | B12: 313 | C12: 819 | D12: 732 | E12: 447 | F12: 895 | G12: 1183 | H12: 1657 | I12: 1510 | J12: 1902 | K12: 1079
A14: Operating Income | B14: =B9-B11-B12 -> 8231 | C14: =C9-C11-C12 -> 8413 | D14: =D9-D11-D12 -> 10173 | E14: =E9-E11-E12 -> 10779 | F14: =F9-F11-F12 -> 10228 | G14: =G9-G11-G12 -> 9708 | H14: =H9-H11-H12 -> 8728 | I14: =I9-I11-I12 -> 8626 | ... K14: =K9-K11-K12 -> 8700
A16: Interest income | B16: 249 | C16: 317 | D16: 483 | E16: 471 | F16: 534 | G16: 594 | H16: 613 | I16: 642 | J16: 677 | K16: 682
A17: Interest expense | B17: 355 | C17: 733 | D17: 417 | E17: 397 | F17: 463 | G17: 483 | H17: 856 | I17: 733 | J17: 841 | K17: 919
A18: Equity income (loss) - net | B18: 781 | C18: 1025 | D18: 690 | E18: 819 | F18: 602 | G18: 769 | H18: 489 | I18: 835 | J18: 1071 | K18: 1008
A19: Other income (loss) - net | B19: 40 | C19: 5185 | D19: 529 | E19: 137 | F19: 576 | G19: -1263 | H19: 631 | I19: -1234 | J19: -1764 | K19: -1121
A21: Income before income taxes | B21: =SUM(B14:B16)-B17+SUM(B18:B19) -> 8946 | C21: =SUM(C14:C16)-C17+SUM(C18:C19) -> 14207 | D21: =SUM(D14:D16)-D17+SUM(D18:D19) -> 11458 | E21: =SUM(E14:E16)-E17+SUM(E18:E19) -> 11809 | F21: =SUM(F14:F16)-F17+SUM(F18:F19) -> 11477 | G21: =SUM(G14:G16)-G17+SUM(G18:G19) -> 9325 | H21: =SUM(H14:H16)-H17+SUM(H18:H19) -> 9605 | I21: =SUM(I14:I16)-I17+SUM(I18:I19) -> 8136 | ... K21: =SUM(K14:K16)-K17+SUM(K18:K19) -> 8350
A23: Income taxes | B23: 2040 | C23: 2370 | D23: 2812 | E23: 2723 | F23: 2851 | G23: 2201 | H23: 2239 | I23: 1586 | J23: 5560 | K23: 1623
A25: CONSOLIDATED NET INCOME | B25: =B21-B23 -> 6906 | C25: =C21-C23 -> 11837 | D25: =D21-D23 -> 8646 | E25: =E21-E23 -> 9086 | F25: =F21-F23 -> 8626 | G25: =G21-G23 -> 7124 | H25: =H21-H23 -> 7366 | I25: =I21-I23 -> 6550 | ... K25: =K21-K23 -> 6727
A27: Less: Net income attributable to noncontrolling interests | B27: 82 | C27: 50 | D27: 62 | E27: 67 | F27: 42 | G27: 26 | H27: 15 | I27: 23 | J27: 35 | K27: 42
A28: Net income from continuing operations | H28: 7366 | I28: 6550 | J28: 1182 | K28: 6727
A29: Income (Loss) from Discontinued Operations, Net of Tax, Including Portion Attributable to Noncontrolling Interest | H29: 0 | I29: 0 | J29: 101 | K29: -251
A31: NET INCOME ATTRIBUTABLE TO SHAREOWNERS OF THE COCA-COLA COMPANY | B31: =B25-B27+B29 -> 6824 | C31: =C25-C27+C29 -> 11787 | D31: =D25-D27+D29 -> 8584 | E31: =E25-E27+E29 -> 9019 | F31: =F25-F27+F29 -> 8584 | G31: =G25-G27+G29 -> 7098 | H31: =H25-H27+H29 -> 7351 | I31: =I25-I27+I29 -> 6527 | ... K31: =K25-K27+K29 -> 6434

Sheet Balance sheet
A2: Balance sheet
A4: Fiscal Year | B4: FY '09 | C4: FY '10 | D4: FY '11 | E4: FY '12 | F4: FY '13 | G4: FY '14 | H4: FY '15 | I4: FY '16 | J4: FY '17 | K4: FY '18
A5: Assets
A6: Cash and cash equivalents | B6: 7021 | C6: 8517 | D6: 12803 | E6: 8442 | F6: 10414 | G6: 8958 | H6: 7309 | I6: 8555 | J6: 6006 | K6: 8926
A7: Short-term investments | B7: 2130 | C7: 2682 | D7: 1088 | E7: 5017 | F7: 6707 | G7: 9052 | H7: 8322 | I7: 9595 | J7: 9352 | K7: 2025
A9: Total cash, cash equivalents and short-term investments | B9: =B6+B7 -> 9151 | C9: =C6+C7 -> 11199 | D9: =D6+D7 -> 13891 | E9: =E6+E7 -> 13459 | F9: =F6+F7 -> 17121 | G9: =G6+G7 -> 18010 | H9: =H6+H7 -> 15631 | I9: =I6+I7 -> 18150 | ... K9: =K6+K7 -> 10951
A11: Marketable securities | B11: 62 | C11: 138 | D11: 144 | E11: 3092 | F11: 3147 | G11: 3665 | H11: 4269 | I11: 4051 | J11: 5317 | K11: 5013
A12: Trade accounts receivable, less allowances | B12: 3758 | C12: 4430 | D12: 4920 | E12: 4759 | F12: 4873 | G12: 4466 | H12: 3941 | I12: 3856 | J12: 3667 | K12: 3396
A13: Inventories | B13: 2354 | C13: 2650 | D13: 3092 | E13: 3264 | F13: 3277 | G13: 3100 | H13: 2902 | I13: 2675 | J13: 2655 | K13: 2766
A14: Prepaid expenses and other assets | B14: 2226 | C14: 3162 | D14: 3450 | E14: 2781 | F14: 2886 | G14: 3066 | H14: 2752 | I14: 2481 | J14: 2000 | K14: 1962
A15: Assets held for sale | D15: 0 | E15: 2973 | F15: 0 | G15: 679 | H15: 3900 | I15: 0 | J15: 7329 | K15: 6546
A16: Assets held for sale | I16: 2797 | J16: 219 | K16: 0
A18: Total current assets | B18: =SUM(B9:B14) -> 17551 | C18: =SUM(C9:C14) -> 21579 | D18: =SUM(D9:D14) -> 25497 | E18: =SUM(E9:E14) -> 27355 | F18: =SUM(F9:F14) -> 31304 | G18: =SUM(G9:G14) -> 32307 | H18: =SUM(H9:H14) -> 29495 | I18: =SUM(I9:I14) -> 31213 | ... K18: =SUM(K9:K14) -> 24088
A20: Equity method investments | B20: 6217 | C20: 6954 | D20: 7233 | E20: 9216 | F20: 10393 | G20: 9947 | H20: 12318 | I20: 16260 | J20: 20856 | K20: 19407
A21: Other investments | B21: 538 | C21: 631 | D21: 1141 | E21: 1232 | F21: 1119 | G21: 3678 | H21: 3470 | I21: 989 | J21: 1096 | K21: 867
A22: Other assets | B22: 1976 | C22: 2121 | D22: 3495 | E22: 3585 | F22: 4661 | G22: 4407 | H22: 4110 | I22: 4248 | J22: 4230 | K22: 4139
A23: Property, plant and equipment - net | B23: 9561 | C23: 14727 | D23: 14939 | E23: 14476 | F23: 14967 | G23: 14633 | H23: 12571 | I23: 10635 | J23: 8203 | K23: 8232
A24: Deferred income tax assets | J24: 330 | K24: 2667
A25: TRADEMARKS WITH INDEFINITE LIVES | B25: 6183 | C25: 6356 | D25: 6430 | E25: 6527 | F25: 6744 | G25: 6533 | H25: 5989 | I25: 6097 | J25: 6729 | K25: 6682
A26: BOTTLERS' FRANCHISE RIGHTS WITH INDEFINITE LIVES | B26: 1953 | C26: 7511 | D26: 7770 | E26: 7405 | F26: 7415 | G26: 6689 | H26: 6000 | I26: 3676 | J26: 138 | K26: 51
A27: Goodwill | B27: 4224 | C27: 11665 | D27: 12219 | E27: 12255 | F27: 12312 | G27: 12100 | H27: 11289 | I27: 10629 | J27: 9401 | K27: 10263
A28: Other intangible assets | B28: 468 | C28: 1377 | D28: 1250 | E28: 1150 | F28: 1140 | G28: 1050 | H28: 854 | I28: 726 | J28: 368 | K28: 274
A30: Total assets | B30: =SUM(A18:B28) -> 48671 | C30: =SUM(B18:C28) -> 121592 | D30: =SUM(C18:D28) -> 152895 | E30: =SUM(D18:E28) -> 163175 | F30: =SUM(E18:F28) -> 173256 | G30: =SUM(F18:G28) -> 181399 | H30: =SUM(G18:H28) -> 177440 | I30: =SUM(H18:I28) -> 170569 | ... K30: =SUM(J18:K28) -> 157018
A32: Liabilities
A34: Accounts payable and accrued expenses | B34: 6657 | C34: 8859 | D34: 9009 | E34: 8680 | F34: 9577 | G34: 9234 | H34: 9660 | I34: 9490 | J34: 8748 | K34: 8932
A35: Loans and notes payable | B35: 6749 | C35: 8100 | D35: 12871 | E35: 16297 | F35: 16901 | G35: 19130 | H35: 13129 | I35: 12498 | J35: 13205 | K35: 13194
A36: Current maturities of long-term debt | B36: 51 | C36: 1276 | D36: 2041 | E36: 1577 | F36: 1024 | G36: 3552 | H36: 2676 | I36: 3527 | J36: 3298 | K36: 4997
A37: Accrued income taxes | B37: 264 | C37: 273 | D37: 362 | E37: 471 | F37: 309 | G37: 400 | H37: 331 | I37: 307 | J37: 410 | K37: 378
A38: Liabilities held for sale | D38: 0 | E38: 796 | F38: 0 | G38: 58 | H38: 1133 | I38: 710 | J38: 37 | K38: 0
A39: Liabilities Held for Sale, Discontinued Operations | I39: 0 | J39: 1496 | K39: 1722
A41: Total current liabilities | B41: =SUM(B34:B39) -> 13721 | C41: =SUM(C34:C39) -> 18508 | D41: =SUM(D34:D39) -> 24283 | E41: =SUM(E34:E39) -> 27821 | F41: =SUM(F34:F39) -> 27811 | G41: =SUM(G34:G39) -> 32374 | H41: =SUM(H34:H39) -> 26929 | I41: =SUM(I34:I39) -> 26532 | ... K41: =SUM(K34:K39) -> 29223
A43: Long-term debt | B43: 5059 | C43: 14041 | D43: 13656 | E43: 14736 | F43: 19154 | G43: 19063 | H43: 28311 | I43: 29684 | J43: 31182 | K43: 25364
A44: Other liabilities | B44: 2965 | C44: 4794 | D44: 5420 | E44: 5468 | F44: 3498 | G44: 4389 | H44: 4301 | I44: 4081 | J44: 8021 | K44: 7638
A45: Deferred income taxes | B45: 1580 | C45: 4261 | D45: 4694 | E45: 4981 | F45: 6152 | G45: 5636 | H45: 4691 | I45: 3753 | J45: 2522 | K45: 1933
A47: Total Liabilities | B47: =SUM(B41:B45) -> 23325 | C47: =SUM(C41:C45) -> 41604 | D47: =SUM(D41:D45) -> 48053 | E47: =SUM(E41:E45) -> 53006 | F47: =SUM(F41:F45) -> 56615 | G47: =SUM(G41:G45) -> 61462 | H47: =SUM(H41:H45) -> 64232 | I47: =SUM(I41:I45) -> 64050 | ... K47: =SUM(K41:K45) -> 64158
A49: Common stock | B49: 880 | C49: 880 | D49: 1760 | E49: 1760 | F49: 1760 | G49: 1760 | H49: 1760 | I49: 1760 | J49: 1760 | K49: 1760
A50: Capital surplus | B50: 8537 | C50: 10057 | D50: 10332 | E50: 11379 | F50: 12276 | G50: 13154 | H50: 14016 | I50: 14993 | J50: 15864 | K50: 16520
A51: Reinvested earnings | B51: 41537 | C51: 49278 | D51: 53621 | E51: 58045 | F51: 61660 | G51: 63408 | H51: 65018 | I51: 65502 | J51: 60430 | K51: 63234
A52: Accumulated other comprehensive income (loss) | B52: -757 | C52: -1450 | D52: -2774 | E52: -3385 | F52: -3432 | G52: -5777 | H52: -10174 | I52: -11205 | J52: -10305 | K52: -12814
A53: Treasury stock, at cost | B53: -25398 | C53: -27762 | D53: -31304 | E53: -35009 | F53: -39091 | G53: -42225 | H53: -45066 | I53: -47988 | J53: -50677 | K53: -51719
...

Sheet Cash flow Statement
A2: Cash Flow Statement
A4: Fiscal Year | B4: FY '09 | C4: FY '10 | D4: FY '11 | E4: FY '12 | F4: FY '13 | G4: FY '14 | H4: FY '15 | I4: FY '16 | J4: FY '17 | K4: FY '18
A6: CONSOLIDATED NET INCOME | B6: ='Profit & Loss Statement'!B$25 -> 6906 | C6: ='Profit & Loss Statement'!C$25 -> 11837 | D6: ='Profit & Loss Statement'!D$25 -> 8646 | E6: ='Profit & Loss Statement'!E$25 -> 9086 | F6: ='Profit & Loss Statement'!F$25 -> 8626 | G6: ='Profit & Loss Statement'!G$25 -> 7124 | H6: ='Profit & Loss Statement'!H$25 -> 7366 | I6: ='Profit & Loss Statement'!I$25 -> 6550 | ... K6: ='Profit & Loss Statement'!K$25 -> 6727
A7: Depreciation and amortization | B7: 1236 | C7: 1443 | D7: 1954 | E7: 1982 | F7: 1977 | G7: 1976 | H7: 1970 | I7: 1787 | J7: 1260 | K7: 1086
A8: (Income) Loss from discontinued operations | H8: 0 | I8: 0 | J8: -101 | K8: 251
A9: Stock-based compensation expense | B9: 241 | C9: 380 | D9: 354 | E9: 259 | F9: 227 | G9: 209 | H9: 236 | I9: 258 | J9: 219 | K9: 225
A10: Deferred income taxes | B10: 353 | C10: 604 | D10: 1035 | E10: 632 | F10: 648 | G10: -40 | H10: 73 | I10: -856 | J10: -1256 | K10: -450
A11: Equity (income) loss - net of dividends | B11: -359 | C11: -671 | D11: -269 | E11: -426 | F11: -201 | G11: -371 | H11: -122 | I11: -449 | J11: -628 | K11: -457
A12: Foreign currency adjustments | B12: 61 | C12: 151 | D12: 7 | E12: -130 | F12: 168 | G12: 415 | H12: -137 | I12: 158 | J12: 281 | K12: -38
A13: Significant (gains) losses on sales of assets - net | B13: -43 | C13: -645 | D13: -220 | E13: -98 | F13: -670 | G13: 831 | H13: -374 | I13: 1146 | J13: 1459 | K13: 189
A14: Other significant (gains) losses - net | B14: 0 | C14: -4713
A15: Other operating charges | B15: 134 | C15: 264 | D15: 214 | E15: 166 | F15: 465 | G15: 761 | H15: 929 | I15: 647 | J15: 1218 | K15: 558
A16: Other items | B16: 221 | C16: 512 | D16: -354 | E16: 254 | F16: 234 | G16: 149 | H16: 744 | I16: -224 | J16: -269 | K16: 682
A17: Net change in operating assets and liabilities | B17: -564 | C17: 370 | D17: -1893 | E17: -1080 | F17: -932 | G17: -439 | H17: -157 | I17: -221 | J17: 3464 | K17: -1202
A19: Net cash provided by operating activities | B19: =SUM(B6:B17) -> 8186 | C19: =SUM(C6:C17) -> 9532 | D19: =SUM(D6:D17) -> 9474 | E19: =SUM(E6:E17) -> 10645 | F19: =SUM(F6:F17) -> 10542 | G19: =SUM(G6:G17) -> 10615 | H19: =SUM(H6:H17) -> 10528 | I19: =SUM(I6:I17) -> 8796 | ... K19: =SUM(K6:K17) -> 7571
A21: Purchases of short-term investments | B21: -2130 | C21: -4579
A22: Purchases of investments | B22: -22 | C22: -132 | D22: -4798 | E22: -14824 | F22: -14782 | G22: -17800 | H22: -15831 | I22: -15499 | J22: -17296 | K22: -7789
A23: Proceeds from disposals of investments | B23: 0 | C23: 4032 | D23: 5811 | E23: 7791 | F23: 12791 | G23: 12986 | H23: 14079 | I23: 16624 | J23: 16694 | K23: 14977
A24: Acquisitions of businesses, equity method investments and nonmarketable securities | B24: -300 | C24: -2511 | D24: -971 | E24: -1486 | F24: -353 | G24: -389 | H24: -2491 | I24: -838 | J24: -3809 | K24: -1040
A25: Proceeds from disposals of businesses, equity method investments and nonmarkatable securities | B25: 240 | C25: 972 | D25: 398 | E25: 20 | F25: 872 | G25: 148 | H25: 565 | I25: 1035 | J25: 3821 | K25: 1362
A26: Purchases of property, plant and equipment | B26: -1993 | C26: -2215 | D26: -2920 | E26: -2780 | F26: -2550 | G26: -2406 | H26: -2553 | I26: -2262 | J26: -1675 | K26: -1347
A27: Proceeds from disposals of property, plant and equipment | B27: 104 | C27: 134 | D27: 101 | E27: 143 | F27: 111 | G27: 223 | H27: 85 | I27: 150 | J27: 104 | K27: 245
A28: Other investing activities | B28: -48 | C28: -106 | D28: -145 | E28: -268 | F28: -303 | G28: -268 | H28: -40 | I28: -209 | J28: -93 | K28: -60
A30: Net cash provided by (used in) investing activities | B30: =SUM(B21:B28) -> -4149 | C30: =SUM(C21:C28) -> -4405 | D30: =SUM(D21:D28) -> -2524 | E30: =SUM(E21:E28) -> -11404 | F30: =SUM(F21:F28) -> -4214 | G30: =SUM(G21:G28) -> -7506 | H30: =SUM(H21:H28) -> -6186 | I30: =SUM(I21:I28) -> -999 | ... K30: =SUM(K21:K28) -> 6348
A32: Issuances of debt | B32: 14689 | C32: 15251 | D32: 27495 | E32: 42791 | F32: 43425 | G32: 41674 | H32: 40434 | I32: 27281 | J32: 29857 | K32: 27339
A33: Payments of debt | B33: -12326 | C33: -13403 | D33: -22530 | E33: -38573 | F33: -38714 | G33: -36962 | H33: -37738 | I33: -25615 | J33: -28768 | K33: -30568
A34: Issuances of stock | B34: 664 | C34: 1666 | D34: 1569 | E34: 1489 | F34: 1328 | G34: 1532 | H34: 1245 | I34: 1434 | J34: 1595 | K34: 1476
A35: Purchases of stock for treasury | B35: -1518 | C35: -2961 | D35: -4513 | E35: -4559 | F35: -4832 | G35: -4162 | H35: -3564 | I35: -3681 | J35: -3682 | K35: -1912
A36: Dividends | B36: -3800 | C36: -4068 | D36: -4300 | E36: -4595 | F36: -4969 | G36: -5350 | H36: -5741 | I36: -6043 | J36: -6320 | K36: -6644
A37: Other financing activities | B37: -2 | C37: 50 | D37: 45 | E37: 100 | F37: 17 | G37: -363 | H37: 251 | I37: 79 | J37: -91 | K37: -243
A39: Net cash provided by (used in) financing activities | B39: =SUM(B32:B37) -> -2293 | C39: =SUM(C32:C37) -> -3465 | D39: =SUM(D32:D37) -> -2234 | E39: =SUM(E32:E37) -> -3347 | F39: =SUM(F32:F37) -> -3745 | G39: =SUM(G32:G37) -> -3631 | H39: =SUM(H32:H37) -> -5113 | I39: =SUM(I32:I37) -> -6545 | ... K39: =SUM(K32:K37) -> -10552
A41: Cash Provided by (Used in) Operating Activities, Discontinued Operations | H41: 0 | I41: 0 | J41: 111 | K41: 307
A42: Effect of exchange rate changes on cash and cash equivalents | B42: 576 | C42: -166 | D42: -430 | E42: -255 | F42: -611 | G42: -934 | H42: -878 | I42: -6 | J42: 241 | K42: -262
A43: Cash Provided by (Used in) Investing Activities, Discontinued Operations | H43: 0 | I43: 0 | J43: -58 | K43: -421
A44: Cash Provided by (Used in) Financing Activities, Discontinued Operations | H44: 0 | I44: 0 | J44: -38 | K44: 205
A45: Net Cash Provided by (Used in) Discontinued Operations | H45: 0 | I45: 0 | J45: 15 | K45: 91
A47: Net increase (decrease) during the year | B47: =SUM(B30,B19,B39)+SUM(B41:B45) -> 2320 | C47: =SUM(C30,C19,C39)+SUM(C41:C45) -> 1496 | D47: =SUM(D30,D19,D39)+SUM(D41:D45) -> 4286 | E47: =SUM(E30,E19,E39)+SUM(E41:E45) -> -4361 | F47: =SUM(F30,F19,F39)+SUM(F41:F45) -> 1972 | G47: =SUM(G30,G19,G39)+SUM(G41:G45) -> -1456 | H47: =SUM(H30,H19,H39)+SUM(H41:H45) -> -1649 | I47: =SUM(I30,I19,I39)+SUM(I41:I45) -> 1246 | ... K47: =SUM(K30,K19,K39)+SUM(K41:K45) -> 3287
